<?xml version="1.0"?>
<robot name="kuka_3dof_arm">

  <!-- Arm base -->
  <link name="arm_base_link">
    <inertial>
      <mass value="0.5"/>
      <origin xyz="0 0 0" rpy="0 0 0"/>
      <inertia ixx="0.002" ixy="0" ixz="0" iyy="0.002" iyz="0" izz="0.002"/>
    </inertial>
    <visual>
      <origin xyz="0 0 0" rpy="0 0 0"/>
      <geometry><cylinder radius="0.05" length="0.06"/></geometry>
      <material name="kuka_orange"><color rgba="1.0 0.5 0.0 1"/></material>
    </visual>
    <collision>
      <origin xyz="0 0 0" rpy="0 0 0"/>
      <geometry><cylinder radius="0.05" length="0.06"/></geometry>
    </collision>
  </link>

  <!-- Link 1 — shoulder -->
  <link name="link1">
    <inertial>
      <mass value="1.2"/>
      <origin xyz="0 0 0.1" rpy="0 0 0"/>
      <inertia ixx="0.01" ixy="0" ixz="0" iyy="0.01" iyz="0" izz="0.003"/>
    </inertial>
    <visual>
      <origin xyz="0 0 0.1" rpy="0 0 0"/>
      <geometry><cylinder radius="0.035" length="0.20"/></geometry>
      <material name="kuka_orange"><color rgba="1.0 0.5 0.0 1"/></material>
    </visual>
    <collision>
      <origin xyz="0 0 0.1" rpy="0 0 0"/>
      <geometry><cylinder radius="0.035" length="0.20"/></geometry>
    </collision>
  </link>
  <joint name="joint1" type="revolute">
    <parent link="arm_base_link"/>
    <child  link="link1"/>
    <origin xyz="0 0 0.03" rpy="0 0 0"/>
    <axis xyz="0 0 1"/>
    <limit lower="-3.14159" upper="3.14159" effort="80" velocity="2.0"/>
    <dynamics damping="0.5" friction="0.1"/>
  </joint>

  <!-- Link 2 — elbow -->
  <link name="link2">
    <inertial>
      <mass value="0.9"/>
      <origin xyz="0 0 0.12" rpy="0 0 0"/>
      <inertia ixx="0.008" ixy="0" ixz="0" iyy="0.008" iyz="0" izz="0.002"/>
    </inertial>
    <visual>
      <origin xyz="0 0 0.12" rpy="0 0 0"/>
      <geometry><cylinder radius="0.030" length="0.24"/></geometry>
      <material name="kuka_orange"><color rgba="1.0 0.5 0.0 1"/></material>
    </visual>
    <collision>
      <origin xyz="0 0 0.12" rpy="0 0 0"/>
      <geometry><cylinder radius="0.030" length="0.24"/></geometry>
    </collision>
  </link>
  <joint name="joint2" type="revolute">
    <parent link="link1"/>
    <child  link="link2"/>
    <origin xyz="0 0 0.20" rpy="0 0 0"/>
    <axis xyz="0 1 0"/>
    <limit lower="-1.5708" upper="1.5708" effort="60" velocity="2.0"/>
    <dynamics damping="0.5" friction="0.1"/>
  </joint>

  <!-- Link 3 — wrist -->
  <link name="link3">
    <inertial>
      <mass value="0.5"/>
      <origin xyz="0 0 0.08" rpy="0 0 0"/>
      <inertia ixx="0.003" ixy="0" ixz="0" iyy="0.003" iyz="0" izz="0.001"/>
    </inertial>
    <visual>
      <origin xyz="0 0 0.08" rpy="0 0 0"/>
      <geometry><cylinder radius="0.025" length="0.16"/></geometry>
      <material name="kuka_dark"><color rgba="0.2 0.2 0.2 1"/></material>
    </visual>
    <collision>
      <origin xyz="0 0 0.08" rpy="0 0 0"/>
      <geometry><cylinder radius="0.025" length="0.16"/></geometry>
    </collision>
  </link>
  <joint name="joint3" type="revolute">
    <parent link="link2"/>
    <child  link="link3"/>
    <origin xyz="0 0 0.24" rpy="0 0 0"/>
    <axis xyz="0 1 0"/>
    <limit lower="-1.5708" upper="1.5708" effort="40" velocity="2.5"/>
    <dynamics damping="0.3" friction="0.05"/>
  </joint>

  <!-- End-effector -->
  <link name="end_effector_link">
    <inertial>
      <mass value="0.1"/>
      <origin xyz="0 0 0" rpy="0 0 0"/>
      <inertia ixx="0.0001" ixy="0" ixz="0" iyy="0.0001" iyz="0" izz="0.0001"/>
    </inertial>
    <visual>
      <origin xyz="0 0 0" rpy="0 0 0"/>
      <geometry><sphere radius="0.018"/></geometry>
      <material name="silver"><color rgba="0.8 0.8 0.8 1"/></material>
    </visual>
  </link>
  <joint name="ee_joint" type="fixed">
    <parent link="link3"/>
    <child  link="end_effector_link"/>
    <origin xyz="0 0 0.16" rpy="0 0 0"/>
  </joint>

  <!-- Gripper base -->
  <link name="gripper_base">
    <inertial>
      <mass value="0.15"/>
      <origin xyz="0 0 0" rpy="0 0 0"/>
      <inertia ixx="0.0003" ixy="0" ixz="0" iyy="0.0003" iyz="0" izz="0.0003"/>
    </inertial>
    <visual>
      <origin xyz="0 0 0.02" rpy="0 0 0"/>
      <geometry><box size="0.06 0.08 0.04"/></geometry>
      <material name="kuka_dark"><color rgba="0.15 0.15 0.15 1"/></material>
    </visual>
    <collision>
      <origin xyz="0 0 0.02" rpy="0 0 0"/>
      <geometry><box size="0.06 0.08 0.04"/></geometry>
    </collision>
  </link>
  <joint name="gripper_base_joint" type="fixed">
    <parent link="end_effector_link"/>
    <child  link="gripper_base"/>
    <origin xyz="0 0 0.01" rpy="0 0 0"/>
  </joint>

  <!-- Left finger -->
  <link name="finger_left">
    <inertial>
      <mass value="0.05"/>
      <origin xyz="0 0 0.025" rpy="0 0 0"/>
      <inertia ixx="0.00005" ixy="0" ixz="0" iyy="0.00005" iyz="0" izz="0.00001"/>
    </inertial>
    <visual>
      <origin xyz="0 0 0.025" rpy="0 0 0"/>
      <geometry><mesh filename="../../assets/meshes/gripper_finger.obj" scale="1 1 1"/></geometry>
      <material name="gray"><color rgba="0.5 0.5 0.5 1"/></material>
    </visual>
    <collision>
      <origin xyz="0 0 0.025" rpy="0 0 0"/>
      <geometry><mesh filename="../../assets/meshes/gripper_finger.obj" scale="1 1 1"/></geometry>
    </collision>
  </link>
  <joint name="finger_left_joint" type="prismatic">
    <parent link="gripper_base"/>
    <child  link="finger_left"/>
    <origin xyz="0  0.025 0.04" rpy="0 0 0"/>
    <axis xyz="0 1 0"/>
    <limit lower="0.0" upper="0.04" effort="20" velocity="0.1"/>
    <dynamics damping="0.1" friction="0.01"/>
  </joint>

  <!-- Right finger -->
  <link name="finger_right">
    <inertial>
      <mass value="0.05"/>
      <origin xyz="0 0 0.025" rpy="0 0 0"/>
      <inertia ixx="0.00005" ixy="0" ixz="0" iyy="0.00005" iyz="0" izz="0.00001"/>
    </inertial>
    <visual>
      <origin xyz="0 0 0.025" rpy="0 0 0"/>
      <geometry><mesh filename="../../assets/meshes/gripper_finger.obj" scale="1 1 1"/></geometry>
      <material name="gray"><color rgba="0.5 0.5 0.5 1"/></material>
    </visual>
    <collision>
      <origin xyz="0 0 0.025" rpy="0 0 0"/>
      <geometry><mesh filename="../../assets/meshes/gripper_finger.obj" scale="1 1 1"/></geometry>
    </collision>
  </link>
  <joint name="finger_right_joint" type="prismatic">
    <parent link="gripper_base"/>
    <child  link="finger_right"/>
    <origin xyz="0 -0.025 0.04" rpy="0 0 0"/>
    <axis xyz="0 -1 0"/>
    <limit lower="0.0" upper="0.04" effort="20" velocity="0.1"/>
    <dynamics damping="0.1" friction="0.01"/>
  </joint>

</robot>